Workbook
Name SlotList: ENUMS!$A$2:$A$7
Name ItemTypeList: ENUMS!$B$2:$B$4
Name RarityList: ENUMS!$C$2:$C$5
Name CoreColorList: ENUMS!$D$2:$D$4
Name AttributeCategoryList: ENUMS!$E$2:$E$4
Name TalentTypeList: ENUMS!$F$2:$F$5
Name WeaponClassList: ENUMS!$G$2:$G$8
Name UnitList: ENUMS!$H$2:$H$3
Name BoolList: ENUMS!$I$2:$I$3
Name SourceTypeList: ENUMS!$J$2:$J$6
Name PatchVersionList: ENUMS!$K$2:$K$13
Name SourceIdList: SOURCES!$A$2:$A$1000
Name BrandIdList: BRANDS!$A$2:$A$1000
Name GearSetIdList: GEAR_SETS!$A$2:$A$1000
Name TalentIdList: TALENTS!$A$2:$A$1000
Name AttributeIdList: ATTRIBUTES!$A$2:$A$1000
Name GearItemIdList: ITEMS_GEAR!$A$2:$A$1000
Name WeaponIdList: WEAPONS!$A$2:$A$1000

Sheet README
A1: The Division 2 — Dataset Template (Build Planner)
A3: How to use:
A4: 1) Fill SOURCES first (where your data came from).
A5: 2) Then BRANDS / GEAR_SETS / TALENTS / ATTRIBUTES.
A6: 3) Then ITEMS_GEAR and ITEM_ATTR_RULES. Finally WEAPONS.
A7: 4) Use BUILD to montar seu set (seleciona item_id / weapon_id e ele calcula brand + gear set bônus).
A8: 5) Use TARGET_LOOT_LOG pra anotar o Targeted Loot do dia/rotação (manual).
A9: URLs:
A10: • wiki_url / logo_url são opcionais (links de referência). image_url é opcional.
A11: Golden rules:
A12: • Everything has an ID (do NOT relate by name).
A13: • Track patch_version + last_updated so you know what's stale.
... A18: • TU/patch naming é teu. Mantém consistente (TU_19, TU_20, etc.)

Sheet ENUMS
A1: Slot | B1: ItemType | C1: Rarity | D1: CoreColor | E1: AttributeCategory | F1: TalentType | G1: WeaponClass | H1: Unit | I1: Bool | J1: SourceType | K1: PatchVersion
A2: Mask | B2: Gear | C2: HighEnd | D2: Red | E2: Offensive | F2: Weapon | G2: AR | H2: % | I2: TRUE | J2: sheet | K2: CURRENT_2026-02
A3: Chest | B3: Weapon | C3: Named | D3: Blue | E3: Defensive | F3: Chest | G3: SMG | H3: flat | I3: FALSE | J3: wiki | K3: Y7S3.2
A4: Backpack | B4: Mod | C4: Exotic | D4: Yellow | E4: Utility | F4: Backpack | G4: LMG | J4: repo | K4: TU24
A5: Gloves | C5: GearSet | F5: GearSet | G5: Rifle | J5: official | K5: TU23
A6: Holster | G6: MMR | J6: other | K6: TU22
A7: Kneepads | G7: Shotgun | K7: TU21
G8: Pistol | K8: TU20
K9: TU19
K10: TU18
K11: TU17
K12: TU16
K13: TU15

Sheet SOURCES
A1: source_id | B1: type | C1: reference | D1: notes | E1: last_updated
A2: SRC_0001 | B2: wiki | C2: The Division Wiki (Fandom) — Brand Sets page | D2: Brand set bonuses used in starter pack | E2: 2026-02-11
A3: SRC_0002 | B3: wiki | C3: The Division Wiki (Fandom) — Gear Sets page | D3: Gear set bonuses used in starter pack | E3: 2026-02-11
A4: SRC_0003 | B4: reddit | C4: r/thedivision wiki — Gear Sets guide | D4: Used to cross-check set bonuses & TU references | E4: 2026-02-11
A5: SRC_0004 | B5: reddit | C5: r/thedivision — Core/minor attributes post (Gear 2.0) | D5: Used as base attribute list (core + minors) | E5: 2026-02-11
A6: SRC_0005 | B6: reddit | C6: https://www.reddit.com/r/thedivision/wiki/thedivision2/guides/equipment/brandset/ | D6: Brand set bonuses (cross-check) | E6: 2026-02-11
A7: SRC_0006 | B7: wiki | C7: https://thedivision.fandom.com/wiki/Talents/Tom_Clancy%27s_The_Division_2 | D7: Talent descriptions (gear talents list) | E7: 2026-02-11
A8: SRC_0007 | B8: wiki | C8: https://thedivision.fandom.com/wiki/In_Sync_(Weapon_Talent) | D8: Weapon talent description: In Sync | E8: 2026-02-11
A9: SRC_0008 | B9: wiki | C9: https://thedivision.fandom.com/wiki/Flatline_(Weapon_Talent) | D9: Weapon talent description: Flatline | E9: 2026-02-11
A10: SRC_0009 | B10: wiki | C10: https://thedivision.fandom.com/wiki/Optimist_(Weapon_Talent) | D10: Weapon talent description: Optimist | E10: 2026-02-11
A11: SRC_0010 | B11: wiki | C11: https://thedivision.fandom.com/wiki/Strained_(Weapon_Talent) | D11: Weapon talent description: Strained | E11: 2026-02-11
A12: SRC_0011 | B12: wiki | C12: https://thedivision.fandom.com/wiki/Fast_Hands_(Weapon_Talent) | D12: Weapon talent description: Fast Hands | E12: 2026-02-11
A13: SRC_0012 | B13: wiki | C13: https://thedivision.fandom.com/wiki/Ranger_(Weapon_Talent) | D13: Weapon talent description: Ranger | E13: 2026-02-11

Sheet BRANDS
A1: brand_id | B1: name | C1: wiki_url | D1: logo_url | E1: bonus_1 | F1: bonus_2 | G1: bonus_3 | H1: notes | I1: source_id | J1: last_updated | K1: patch_version
A2: BRD_0001 | B2: Providence Defense | E2: +13% Headshot Damage | F2: +8% Critical Hit Chance | G2: +13% Critical Hit Damage | I2: SRC_0001 | J2: 2026-02-11 | K2: CURRENT_2026-02
A3: BRD_0002 | B3: Fenris Group AB | E3: +10% Assault Rifle Damage | F3: +30% Reload Speed | G3: +50% Stability | I3: SRC_0001 | J3: 2026-02-11 | K3: CURRENT_2026-02
A4: BRD_0003 | B4: Grupo Sombra S.A. | E4: +13% Critical Hit Damage | F4: +20% Explosives Damage | G4: +13% Headshot Damage | I4: SRC_0001 | J4: 2026-02-11 | K4: CURRENT_2026-02
A5: BRD_0004 | B5: Česká Výroba S.R.O. | E5: +8% Critical Hit Chance | F5: +20% Hazard Protection | G5: +90% Health | I5: SRC_0001 | J5: 2026-02-11 | K5: CURRENT_2026-02
A6: BRD_0005 | B6: Sokolov Concern | E6: +10% SMG Damage | F6: +13% Critical Hit Damage | G6: +8% Critical Hit Chance | I6: SRC_0001 | J6: 2026-02-11 | K6: CURRENT_2026-02
A7: BRD_0006 | B7: Walker, Harris & Co. | E7: +5% Weapon Damage | F7: +5% Damage to Armor | G7: +10% Damage to Health | I7: SRC_0001 | J7: 2026-02-11 | K7: CURRENT_2026-02
A8: BRD_0007 | B8: Overlord Armaments | E8: +10% Rifle Damage | F8: +20% Accuracy | G8: +10% Weapon Handling | I8: SRC_0001 | J8: 2026-02-11 | K8: CURRENT_2026-02
A9: BRD_0008 | B9: Petrov Defense Group | E9: +10% LMG Damage | F9: +10% Weapon Handling | G9: +20% Ammo Capacity | I9: SRC_0001 | J9: 2026-02-11 | K9: CURRENT_2026-02
A10: BRD_0009 | B10: Alps Summit Armament | E10: +18% Skill Repair | F10: +30% Skill Duration | G10: +30% Skill Haste | I10: SRC_0001 | J10: 2026-02-11 | K10: CURRENT_2026-02
A11: BRD_0010 | B11: China Light Industries Corporation | E11: +15% Explosive Damage | F11: +20% Skill Haste | G11: +25% Status Effects | I11: SRC_0001 | J11: 2026-02-11 | K11: CURRENT_2026-02
A12: BRD_0011 | B12: Empress International | E12: +10% Skill Health | F12: +10% Skill Damage | G12: +8% Skill Efficiency | I12: SRC_0001 | J12: 2026-02-11 | K12: CURRENT_2026-02
A13: BRD_0012 | B13: Belstone Armory | E13: +1% Armor Regen | F13: +10% Armor on Kill | G13: +45% Incoming Repairs | I13: SRC_0001 | J13: 2026-02-11 | K13: CURRENT_2026-02
... A19: BRD_0018 | B19: Wyvern Wear | E19: +8% Skill Damage | F19: +18% Status Effects | G19: +45% Skill Duration | I19: SRC_0001 | J19: 2026-02-11 | K19: CURRENT_2026-02

Sheet GEAR_SETS
A1: set_id | B1: name | C1: wiki_url | D1: logo_url | E1: bonus_2 | F1: bonus_3 | G1: bonus_4 | H1: notes | I1: source_id | J1: last_updated | K1: patch_version
A2: GST_0001 | B2: Striker's Battlegear | E2: +15% Weapon Handling | F2: +15% Rate of Fire | G2: Striker's Gamble | I2: SRC_0002 | J2: 2026-02-11 | K2: CURRENT_2026-02
A3: GST_0002 | B3: Heartbreaker | E3: +15% Assault Rifle Damage +15% LMG Damage | F3: +15% Weapon Handling | G3: Heartstopper | I3: SRC_0002 | J3: 2026-02-11 | K3: CURRENT_2026-02
A4: GST_0003 | B4: Hunter's Fury | E4: +15% Shotgun Damage | F4: +15% SMG Damage +20% Armor on Kill | G4: Apex Predator (+50% Health on Kill) | I4: SRC_0002 | J4: 2026-02-11 | K4: CURRENT_2026-02
A5: GST_0004 | B5: Negotiator's Dilemma | E5: +15% Critical Hit Chance | F5: +20% Critical Hit Damage | G5: Hostile Negotiations | I5: SRC_0002 | J5: 2026-02-11 | K5: CURRENT_2026-02
A6: GST_0005 | B6: Hotshot | E6: +30% Marksman Rifle Damage | F6: +30% Weapon Handling +30% Headshot Damage | G6: Headache | I6: SRC_0002 | J6: 2026-02-11 | K6: CURRENT_2026-02
A7: GST_0006 | B7: Eclipse Protocol | E7: +15% Status Effects | F7: +15% Skill Haste +30% Hazard Protection | G7: Indirect Transmission | I7: SRC_0002 | J7: 2026-02-11 | K7: CURRENT_2026-02
A8: GST_0007 | B8: Foundry Bulwark | E8: +10% Total Armor | F8: +1% Armor Regeneration +50% Shield Health | G8: Makeshift Repairs | I8: SRC_0002 | J8: 2026-02-11 | K8: CURRENT_2026-02
A9: GST_0008 | B9: Future Initiative | E9: +30% Repair Skills | F9: +15% Skill Haste +30% Skill Duration | G9: Ground Control | I9: SRC_0002 | J9: 2026-02-11 | K9: CURRENT_2026-02
A10: GST_0009 | B10: Umbra Initiative | E10: +15% Critical Chance | F10: +30% Reload Speed | G10: From the Shadows / Into the Light | I10: SRC_0003 | J10: 2026-02-11 | K10: CURRENT_2026-02
A11: GST_0010 | B11: Tip of the Spear | E11: +20% Signature Weapon Damage | F11: +10% Weapon Damage | G11: Aggressive Recon | I11: SRC_0003 | J11: 2026-02-11 | K11: CURRENT_2026-02

Sheet TALENTS
A1: talent_id | B1: name | C1: type | D1: description | E1: cooldown_s | F1: conditions | G1: wiki_url | H1: source_id | I1: last_updated | J1: patch_version
A2: TLT_0001 | B2: Vigilance | C2: Backpack | D2: +25% dano total da arma; ao tomar dano o bônus desliga por 4s. | E2: 4 | F2: Desativa ao tomar dano | G2: https://thedivision.fandom.com/wiki/Talents/Tom_Clancy%27s_The_Division_2 | H2: SRC_0006 | I2: 2026-02-11 | J2: CURRENT_2026-02
A3: TLT_0002 | B3: Adrenaline Rush | C3: Backpack | D3: Ao ficar a até 10m de inimigo: ganha 20% de armadura bônus por 5s; acumula até 3; CD 5s. | E3: 5 | F3: Até 10m do inimigo; stacks 3 | G3: https://thedivision.fandom.com/wiki/Talents/Tom_Clancy%27s_The_Division_2 | H3: SRC_0006 | I3: 2026-02-11 | J3: CURRENT_2026-02
A4: TLT_0003 | B4: Bloodsucker | C4: Backpack | D4: Kill dá stack de +10% armadura bônus por 10s; renova stacks; máximo 10 stacks. | F4: Ao matar; stacks 10 | G4: https://thedivision.fandom.com/wiki/Talents/Tom_Clancy%27s_The_Division_2 | H4: SRC_0006 | I4: 2026-02-11 | J4: CURRENT_2026-02
A5: TLT_0004 | B5: Companion | C5: Backpack | D5: Dentro de 5m de aliado ou skill: +15% dano total da arma. | F5: Até 5m de aliado/skill | G5: https://thedivision.fandom.com/wiki/Talents/Tom_Clancy%27s_The_Division_2 | H5: SRC_0006 | I5: 2026-02-11 | J5: CURRENT_2026-02
A6: TLT_0005 | B6: Unbreakable | C6: Chest | D6: Quando a armadura zera: repara 95% da armadura. CD 60s. | E6: 60 | F6: Ao ficar sem armadura | G6: https://thedivision.fandom.com/wiki/Talents/Tom_Clancy%27s_The_Division_2 | H6: SRC_0006 | I6: 2026-02-11 | J6: CURRENT_2026-02
A7: TLT_0006 | B7: Obliterate | C7: Chest | D7: Crítico: +1% dano total da arma por 5s; acumula até 25 stacks. | F7: Crit hits; stacks 25 | G7: https://thedivision.fandom.com/wiki/Talents/Tom_Clancy%27s_The_Division_2 | H7: SRC_0006 | I7: 2026-02-11 | J7: CURRENT_2026-02
A8: TLT_0007 | B8: Glass Cannon | C8: Chest | D8: Você causa +25% dano (amplificado), mas recebe +50% dano (amplificado). | F8: Sempre ativo | G8: https://thedivision.fandom.com/wiki/Talents/Tom_Clancy%27s_The_Division_2 | H8: SRC_0006 | I8: 2026-02-11 | J8: CURRENT_2026-02
A9: TLT_0008 | B9: Spotter | C9: Chest | D9: Amplifica dano de arma e skill em 15% contra inimigos “pulsed”. | F9: Alvos com Pulse | G9: https://thedivision.fandom.com/wiki/Talents/Tom_Clancy%27s_The_Division_2 | H9: SRC_0006 | I9: 2026-02-11 | J9: CURRENT_2026-02
A10: TLT_0009 | B10: Braced | C10: Chest | D10: Enquanto em cover: +45% weapon handling. | F10: Em cover | G10: https://thedivision.fandom.com/wiki/Talents/Tom_Clancy%27s_The_Division_2 | H10: SRC_0006 | I10: 2026-02-11 | J10: CURRENT_2026-02
A11: TLT_0010 | B11: In Sync | C11: Weapon | D11: Acertar inimigo: +15% dano de skill por 5s. Usar skill (não-shield) ou dano de skill: +15% dano de arma por 5s. Com os dois: bônus dobrado. | E11: 5 | F11: Buffs 5s; dobra com ambos | G11: https://thedivision.fandom.com/wiki/In_Sync_%28Weapon_Talent%29 | H11: SRC_0007 | I11: 2026-02-11 | J11: CURRENT_2026-02
A12: TLT_0011 | B12: Flatline | C12: Weapon | D12: Amplifica dano da arma em 15% contra alvos com Pulse. Após 3 kills, aplica Pulse no próximo inimigo atingido. | F12: Pulse; após 3 kills | G12: https://thedivision.fandom.com/wiki/Flatline_%28Weapon_Talent%29 | H12: SRC_0008 | I12: 2026-02-11 | J12: CURRENT_2026-02
A13: TLT_0012 | B13: Optimist | C13: Weapon | D13: Dano da arma +3.5% a cada 10% de munição faltando no pente. | F13: Por % munição faltando | G13: https://thedivision.fandom.com/wiki/Optimist_%28Weapon_Talent%29 | H13: SRC_0009 | I13: 2026-02-11 | J13: CURRENT_2026-02
A14: TLT_0013 | B14: Strained | C14: Weapon | D14: Enquanto atira: a cada 0.5s ganha +10% dano crítico; acumula até 5 stacks. | F14: Atirando contínuo; stacks 5 | G14: https://thedivision.fandom.com/wiki/Strained_%28Weapon_Talent%29 | H14: SRC_0010 | I14: 2026-02-11 | J14: CURRENT_2026-02
A15: TLT_0014 | B15: Fast Hands | C15: Weapon | D15: Críticos dão stack de +3% velocidade de recarga; máximo 40 stacks. | F15: Crit hits; stacks 40 | G15: https://thedivision.fandom.com/wiki/Fast_Hands_%28Weapon_Talent%29 | H15: SRC_0011 | I15: 2026-02-11 | J15: CURRENT_2026-02
A16: TLT_0015 | B16: Ranger | C16: Weapon | D16: Amplifica dano da arma em 2% a cada 5m de distância do alvo. | F16: Distância ao alvo | G16: https://thedivision.fandom.com/wiki/Ranger_%28Weapon_Talent%29 | H16: SRC_0012 | I16: 2026-02-11 | J16: CURRENT_2026-02

Sheet ATTRIBUTES
A1: attr_id | B1: name | C1: category | D1: unit | E1: notes | F1: source_id | G1: last_updated | H1: patch_version
A2: ATT_0001 | B2: Weapon Damage | C2: Offensive | D2: % | E2: Core attribute | F2: SRC_0004 | G2: 2026-02-11 | H2: CURRENT_2026-02
A3: ATT_0002 | B3: Armor | C3: Defensive | D3: flat | E3: Core attribute | F3: SRC_0004 | G3: 2026-02-11 | H3: CURRENT_2026-02
A4: ATT_0003 | B4: Skill Tier | C4: Utility | D4: flat | E4: Core attribute (tier) | F4: SRC_0004 | G4: 2026-02-11 | H4: CURRENT_2026-02
A5: ATT_0010 | B5: Critical Hit Chance | C5: Offensive | D5: % | E5: Minor attribute | F5: SRC_0004 | G5: 2026-02-11 | H5: CURRENT_2026-02
A6: ATT_0011 | B6: Critical Hit Damage | C6: Offensive | D6: % | E6: Minor attribute | F6: SRC_0004 | G6: 2026-02-11 | H6: CURRENT_2026-02
A7: ATT_0012 | B7: Headshot Damage | C7: Offensive | D7: % | E7: Minor attribute | F7: SRC_0004 | G7: 2026-02-11 | H7: CURRENT_2026-02
A8: ATT_0013 | B8: Weapon Handling | C8: Offensive | D8: % | E8: Minor attribute | F8: SRC_0004 | G8: 2026-02-11 | H8: CURRENT_2026-02
A9: ATT_0020 | B9: Health | C9: Defensive | D9: flat | E9: Minor attribute | F9: SRC_0004 | G9: 2026-02-11 | H9: CURRENT_2026-02
A10: ATT_0021 | B10: Armor Regeneration | C10: Defensive | D10: flat | E10: Minor attribute (per second) | F10: SRC_0004 | G10: 2026-02-11 | H10: CURRENT_2026-02
A11: ATT_0022 | B11: Hazard Protection | C11: Defensive | D11: % | E11: Minor attribute | F11: SRC_0004 | G11: 2026-02-11 | H11: CURRENT_2026-02
A12: ATT_0023 | B12: Explosive Resistance | C12: Defensive | D12: % | E12: Minor attribute | F12: SRC_0004 | G12: 2026-02-11 | H12: CURRENT_2026-02
... A16: ATT_0033 | B16: Status Effects | C16: Utility | D16: % | E16: Minor attribute | F16: SRC_0004 | G16: 2026-02-11 | H16: CURRENT_2026-02

Sheet ITEMS_GEAR
A1: item_id | B1: name | C1: slot | D1: rarity | E1: brand_id | F1: set_id | G1: is_named | H1: is_exotic | I1: core_color | J1: core_count | K1: mod_slots | L1: talent_id | M1: image_url | N1: wiki_url | O1: target_loot_ref | P1: notes | Q1: source_id | R1: last_updated | S1: patch_version
A301: ITG_0001 | C301: Mask | D301: HighEnd | G301: FALSE | H301: FALSE | I301: Red | J301: 1 | K301: 0 | O301: Mask | Q301: SRC_0001 | S301: TU_??

Sheet ITEM_ATTR_RULES
A1: rule_id | B1: item_id | C1: attr_id | D1: is_core | E1: is_minor | F1: min_value | G1: max_value | H1: notes | I1: source_id | J1: last_updated | K1: patch_version
A301: RUL_0001 | B301: ITG_0001 | C301: ATT_0001 | D301: FALSE | E301: TRUE | I301: SRC_0001 | K301: TU_??

Sheet WEAPONS
A1: weapon_id | B1: name | C1: class | D1: rarity | E1: is_named | F1: is_exotic | G1: base_damage | H1: rpm | I1: mag_size | J1: talent_id | K1: image_url | L1: wiki_url | M1: target_loot_ref | N1: notes | O1: source_id | P1: last_updated | Q1: patch_version
A301: WPN_0001 | C301: AR | D301: HighEnd | E301: FALSE | F301: FALSE | M301: AR | O301: SRC_0001 | Q301: TU_??

Sheet BUILD
A1: TD2 Build Planner (Starter)
A2: Preencha os IDs nas colunas amarelas. O resto puxa automático.
A4: GEAR (6 peças)
A5: slot | B5: item_id | C5: name | D5: brand_id | E5: set_id | F5: core_color | G5: talent_id | H5: talent_name | I5: talent_description | J5: target_loot_ref | K5: wiki_url | L5: notes
A6: Mask | C6: =IF($B6="","",IFERROR(VLOOKUP($B6,ITEMS_GEAR!$A:$S,2,FALSE),"")) | D6: =IF($B6="","",IFERROR(VLOOKUP($B6,ITEMS_GEAR!$A:$S,5,FALSE),"")) | E6: =IF($B6="","",IFERROR(VLOOKUP($B6,ITEMS_GEAR!$A:$S,6,FALSE),"")) | F6: =IF($B6="","",IFERROR(VLOOKUP($B6,ITEMS_GEAR!$A:$S,9,FALSE),"")) | G6: =IF($B6="","",IFERROR(VLOOKUP($B6,ITEMS_GEAR!$A:$S,12,FALSE),"")) | H6: =IF($G6="","",IFERROR(VLOOKUP($G6,TALENTS!$A:$J,2,FALSE),"")) | I6: =IF($G6="","",IFERROR(VLOOKUP($G6,TALENTS!$A:$J,4,FALSE),"")) | J6: =IF($B6="","",IFERROR(VLOOKUP($B6,ITEMS_GEAR!$A:$S,15,FALSE),"")) | K6: =IF($B6="","",IFERROR(VLOOKUP($B6,ITEMS_GEAR!$A:$S,14,FALSE),""))
A7: Chest | C7: =IF($B7="","",IFERROR(VLOOKUP($B7,ITEMS_GEAR!$A:$S,2,FALSE),"")) | D7: =IF($B7="","",IFERROR(VLOOKUP($B7,ITEMS_GEAR!$A:$S,5,FALSE),"")) | E7: =IF($B7="","",IFERROR(VLOOKUP($B7,ITEMS_GEAR!$A:$S,6,FALSE),"")) | F7: =IF($B7="","",IFERROR(VLOOKUP($B7,ITEMS_GEAR!$A:$S,9,FALSE),"")) | G7: =IF($B7="","",IFERROR(VLOOKUP($B7,ITEMS_GEAR!$A:$S,12,FALSE),"")) | H7: =IF($G7="","",IFERROR(VLOOKUP($G7,TALENTS!$A:$J,2,FALSE),"")) | I7: =IF($G7="","",IFERROR(VLOOKUP($G7,TALENTS!$A:$J,4,FALSE),"")) | J7: =IF($B7="","",IFERROR(VLOOKUP($B7,ITEMS_GEAR!$A:$S,15,FALSE),"")) | K7: =IF($B7="","",IFERROR(VLOOKUP($B7,ITEMS_GEAR!$A:$S,14,FALSE),""))
A8: Backpack | C8: =IF($B8="","",IFERROR(VLOOKUP($B8,ITEMS_GEAR!$A:$S,2,FALSE),"")) | D8: =IF($B8="","",IFERROR(VLOOKUP($B8,ITEMS_GEAR!$A:$S,5,FALSE),"")) | E8: =IF($B8="","",IFERROR(VLOOKUP($B8,ITEMS_GEAR!$A:$S,6,FALSE),"")) | F8: =IF($B8="","",IFERROR(VLOOKUP($B8,ITEMS_GEAR!$A:$S,9,FALSE),"")) | G8: =IF($B8="","",IFERROR(VLOOKUP($B8,ITEMS_GEAR!$A:$S,12,FALSE),"")) | H8: =IF($G8="","",IFERROR(VLOOKUP($G8,TALENTS!$A:$J,2,FALSE),"")) | I8: =IF($G8="","",IFERROR(VLOOKUP($G8,TALENTS!$A:$J,4,FALSE),"")) | J8: =IF($B8="","",IFERROR(VLOOKUP($B8,ITEMS_GEAR!$A:$S,15,FALSE),"")) | K8: =IF($B8="","",IFERROR(VLOOKUP($B8,ITEMS_GEAR!$A:$S,14,FALSE),""))
A9: Gloves | C9: =IF($B9="","",IFERROR(VLOOKUP($B9,ITEMS_GEAR!$A:$S,2,FALSE),"")) | D9: =IF($B9="","",IFERROR(VLOOKUP($B9,ITEMS_GEAR!$A:$S,5,FALSE),"")) | E9: =IF($B9="","",IFERROR(VLOOKUP($B9,ITEMS_GEAR!$A:$S,6,FALSE),"")) | F9: =IF($B9="","",IFERROR(VLOOKUP($B9,ITEMS_GEAR!$A:$S,9,FALSE),"")) | G9: =IF($B9="","",IFERROR(VLOOKUP($B9,ITEMS_GEAR!$A:$S,12,FALSE),"")) | H9: =IF($G9="","",IFERROR(VLOOKUP($G9,TALENTS!$A:$J,2,FALSE),"")) | I9: =IF($G9="","",IFERROR(VLOOKUP($G9,TALENTS!$A:$J,4,FALSE),"")) | J9: =IF($B9="","",IFERROR(VLOOKUP($B9,ITEMS_GEAR!$A:$S,15,FALSE),"")) | K9: =IF($B9="","",IFERROR(VLOOKUP($B9,ITEMS_GEAR!$A:$S,14,FALSE),""))
A10: Holster | C10: =IF($B10="","",IFERROR(VLOOKUP($B10,ITEMS_GEAR!$A:$S,2,FALSE),"")) | D10: =IF($B10="","",IFERROR(VLOOKUP($B10,ITEMS_GEAR!$A:$S,5,FALSE),"")) | E10: =IF($B10="","",IFERROR(VLOOKUP($B10,ITEMS_GEAR!$A:$S,6,FALSE),"")) | F10: =IF($B10="","",IFERROR(VLOOKUP($B10,ITEMS_GEAR!$A:$S,9,FALSE),"")) | G10: =IF($B10="","",IFERROR(VLOOKUP($B10,ITEMS_GEAR!$A:$S,12,FALSE),"")) | H10: =IF($G10="","",IFERROR(VLOOKUP($G10,TALENTS!$A:$J,2,FALSE),"")) | I10: =IF($G10="","",IFERROR(VLOOKUP($G10,TALENTS!$A:$J,4,FALSE),"")) | J10: =IF($B10="","",IFERROR(VLOOKUP($B10,ITEMS_GEAR!$A:$S,15,FALSE),"")) | K10: =IF($B10="","",IFERROR(VLOOKUP($B10,ITEMS_GEAR!$A:$S,14,FALSE),""))
A11: Kneepads | C11: =IF($B11="","",IFERROR(VLOOKUP($B11,ITEMS_GEAR!$A:$S,2,FALSE),"")) | D11: =IF($B11="","",IFERROR(VLOOKUP($B11,ITEMS_GEAR!$A:$S,5,FALSE),"")) | E11: =IF($B11="","",IFERROR(VLOOKUP($B11,ITEMS_GEAR!$A:$S,6,FALSE),"")) | F11: =IF($B11="","",IFERROR(VLOOKUP($B11,ITEMS_GEAR!$A:$S,9,FALSE),"")) | G11: =IF($B11="","",IFERROR(VLOOKUP($B11,ITEMS_GEAR!$A:$S,12,FALSE),"")) | H11: =IF($G11="","",IFERROR(VLOOKUP($G11,TALENTS!$A:$J,2,FALSE),"")) | I11: =IF($G11="","",IFERROR(VLOOKUP($G11,TALENTS!$A:$J,4,FALSE),"")) | J11: =IF($B11="","",IFERROR(VLOOKUP($B11,ITEMS_GEAR!$A:$S,15,FALSE),"")) | K11: =IF($B11="","",IFERROR(VLOOKUP($B11,ITEMS_GEAR!$A:$S,14,FALSE),""))
A13: CORE COUNT | B13: Red | C13: Blue | D13: Yellow
B14: =COUNTIF($F$6:$F$11,"Red") | C14: =COUNTIF($F$6:$F$11,"Blue") | D14: =COUNTIF($F$6:$F$11,"Yellow")
A16: BRAND SUMMARY (auto - filtra pelos com Pieces > 0)
A17: brand_id | B17: brand_name | C17: pieces | D17: bonus_1 | E17: bonus_2 | F17: bonus_3
A18: =BRANDS!A2 | B18: =BRANDS!B2 | C18: =COUNTIF($D$6:$D$11,$A18) | D18: =IF($C18>=1,BRANDS!E2,"") | E18: =IF($C18>=2,BRANDS!F2,"") | F18: =IF($C18>=3,BRANDS!G2,"")
A19: =BRANDS!A3 | B19: =BRANDS!B3 | C19: =COUNTIF($D$6:$D$11,$A19) | D19: =IF($C19>=1,BRANDS!E3,"") | E19: =IF($C19>=2,BRANDS!F3,"") | F19: =IF($C19>=3,BRANDS!G3,"")
A20: =BRANDS!A4 | B20: =BRANDS!B4 | C20: =COUNTIF($D$6:$D$11,$A20) | D20: =IF($C20>=1,BRANDS!E4,"") | E20: =IF($C20>=2,BRANDS!F4,"") | F20: =IF($C20>=3,BRANDS!G4,"")
A21: =BRANDS!A5 | B21: =BRANDS!B5 | C21: =COUNTIF($D$6:$D$11,$A21) | D21: =IF($C21>=1,BRANDS!E5,"") | E21: =IF($C21>=2,BRANDS!F5,"") | F21: =IF($C21>=3,BRANDS!G5,"")
A22: =BRANDS!A6 | B22: =BRANDS!B6 | C22: =COUNTIF($D$6:$D$11,$A22) | D22: =IF($C22>=1,BRANDS!E6,"") | E22: =IF($C22>=2,BRANDS!F6,"") | F22: =IF($C22>=3,BRANDS!G6,"")
A23: =BRANDS!A7 | B23: =BRANDS!B7 | C23: =COUNTIF($D$6:$D$11,$A23) | D23: =IF($C23>=1,BRANDS!E7,"") | E23: =IF($C23>=2,BRANDS!F7,"") | F23: =IF($C23>=3,BRANDS!G7,"")
A24: =BRANDS!A8 | B24: =BRANDS!B8 | C24: =COUNTIF($D$6:$D$11,$A24) | D24: =IF($C24>=1,BRANDS!E8,"") | E24: =IF($C24>=2,BRANDS!F8,"") | F24: =IF($C24>=3,BRANDS!G8,"")
A25: =BRANDS!A9 | B25: =BRANDS!B9 | C25: =COUNTIF($D$6:$D$11,$A25) | D25: =IF($C25>=1,BRANDS!E9,"") | E25: =IF($C25>=2,BRANDS!F9,"") | F25: =IF($C25>=3,BRANDS!G9,"")
A26: =BRANDS!A10 | B26: =BRANDS!B10 | C26: =COUNTIF($D$6:$D$11,$A26) | D26: =IF($C26>=1,BRANDS!E10,"") | E26: =IF($C26>=2,BRANDS!F10,"") | F26: =IF($C26>=3,BRANDS!G10,"")
A27: =BRANDS!A11 | B27: =BRANDS!B11 | C27: =COUNTIF($D$6:$D$11,$A27) | D27: =IF($C27>=1,BRANDS!E11,"") | E27: =IF($C27>=2,BRANDS!F11,"") | F27: =IF($C27>=3,BRANDS!G11,"")
A28: =BRANDS!A12 | B28: =BRANDS!B12 | C28: =COUNTIF($D$6:$D$11,$A28) | D28: =IF($C28>=1,BRANDS!E12,"") | E28: =IF($C28>=2,BRANDS!F12,"") | F28: =IF($C28>=3,BRANDS!G12,"")
A29: =BRANDS!A13 | B29: =BRANDS!B13 | C29: =COUNTIF($D$6:$D$11,$A29) | D29: =IF($C29>=1,BRANDS!E13,"") | E29: =IF($C29>=2,BRANDS!F13,"") | F29: =IF($C29>=3,BRANDS!G13,"")
... A32: =BRANDS!A16 | B32: =BRANDS!B16 | C32: =COUNTIF($D$6:$D$11,$A32) | D32: =IF($C32>=1,BRANDS!E16,"") | E32: =IF($C32>=2,BRANDS!F16,"") | F32: =IF($C32>=3,BRANDS!G16,"")
A35: GEAR SET SUMMARY (Pieces >= 2)
A36: set_id | B36: set_name | C36: pieces | D36: bonus_2 | E36: bonus_3 | F36: bonus_4 | G36: wiki_url
A37: =GEAR_SETS!A2 | B37: =GEAR_SETS!B2 | C37: =COUNTIF($E$6:$E$11,$A37) | D37: =IF($C37>=2,GEAR_SETS!E2,"") | E37: =IF($C37>=3,GEAR_SETS!F2,"") | F37: =IF($C37>=4,GEAR_SETS!G2,"") | G37: =GEAR_SETS!C2
A38: =GEAR_SETS!A3 | B38: =GEAR_SETS!B3 | C38: =COUNTIF($E$6:$E$11,$A38) | D38: =IF($C38>=2,GEAR_SETS!E3,"") | E38: =IF($C38>=3,GEAR_SETS!F3,"") | F38: =IF($C38>=4,GEAR_SETS!G3,"") | G38: =GEAR_SETS!C3
A39: =GEAR_SETS!A4 | B39: =GEAR_SETS!B4 | C39: =COUNTIF($E$6:$E$11,$A39) | D39: =IF($C39>=2,GEAR_SETS!E4,"") | E39: =IF($C39>=3,GEAR_SETS!F4,"") | F39: =IF($C39>=4,GEAR_SETS!G4,"") | G39: =GEAR_SETS!C4
A40: =GEAR_SETS!A5 | B40: =GEAR_SETS!B5 | C40: =COUNTIF($E$6:$E$11,$A40) | D40: =IF($C40>=2,GEAR_SETS!E5,"") | E40: =IF($C40>=3,GEAR_SETS!F5,"") | F40: =IF($C40>=4,GEAR_SETS!G5,"") | G40: =GEAR_SETS!C5
A41: =GEAR_SETS!A6 | B41: =GEAR_SETS!B6 | C41: =COUNTIF($E$6:$E$11,$A41) | D41: =IF($C41>=2,GEAR_SETS!E6,"") | E41: =IF($C41>=3,GEAR_SETS!F6,"") | F41: =IF($C41>=4,GEAR_SETS!G6,"") | G41: =GEAR_SETS!C6
A42: =GEAR_SETS!A7 | B42: =GEAR_SETS!B7 | C42: =COUNTIF($E$6:$E$11,$A42) | D42: =IF($C42>=2,GEAR_SETS!E7,"") | E42: =IF($C42>=3,GEAR_SETS!F7,"") | F42: =IF($C42>=4,GEAR_SETS!G7,"") | G42: =GEAR_SETS!C7
A43: =GEAR_SETS!A8 | B43: =GEAR_SETS!B8 | C43: =COUNTIF($E$6:$E$11,$A43) | D43: =IF($C43>=2,GEAR_SETS!E8,"") | E43: =IF($C43>=3,GEAR_SETS!F8,"") | F43: =IF($C43>=4,GEAR_SETS!G8,"") | G43: =GEAR_SETS!C8
A44: =GEAR_SETS!A9 | B44: =GEAR_SETS!B9 | C44: =COUNTIF($E$6:$E$11,$A44) | D44: =IF($C44>=2,GEAR_SETS!E9,"") | E44: =IF($C44>=3,GEAR_SETS!F9,"") | F44: =IF($C44>=4,GEAR_SETS!G9,"") | G44: =GEAR_SETS!C9
A45: =GEAR_SETS!A10 | B45: =GEAR_SETS!B10 | C45: =COUNTIF($E$6:$E$11,$A45) | D45: =IF($C45>=2,GEAR_SETS!E10,"") | E45: =IF($C45>=3,GEAR_SETS!F10,"") | F45: =IF($C45>=4,GEAR_SETS!G10,"") | G45: =GEAR_SETS!C10
A48: WEAPONS
A49: slot | B49: weapon_id | C49: name | D49: class | E49: talent_id | F49: talent_name | G49: talent_description | H49: target_loot_ref | I49: wiki_url | J49: notes
...

Sheet TARGET_LOOT_LOG
A1: Targeted Loot Log (manual)
A2: date | B2: location_type | C2: location_name | D2: target_loot_ref | E2: target_loot_name | F2: source_url | G2: notes
